<?xml version="1.0" encoding="utf-8"?><testsuites name="pytest tests"><testsuite name="pytest" errors="0" failures="3" skipped="0" tests="3" time="2.222" timestamp="2025-09-11T10:56:24.015286+00:00" hostname="an"><testcase classname="tests.integration.test_real_world_validation.TestRealWorldNetworkValidation" name="test_testnet_horizon_connectivity" time="0.027"><failure message="AttributeError: 'coroutine' object has no attribute 'network_passphrase'">#x1B[1m#x1B[31mtests/integration/test_real_world_validation.py#x1B[0m:78: in test_testnet_horizon_connectivity
    #x1B[0mchain_interface = ModernStellarChainInterface(#x1B[90m#x1B[39;49;00m
#x1B[1m#x1B[31mhummingbot/connector/exchange/stellar/stellar_chain_interface.py#x1B[0m:68: in __init__
    #x1B[0m#x1B[96mself#x1B[39;49;00m.network_passphrase = config.network_passphrase#x1B[90m#x1B[39;49;00m
                              ^^^^^^^^^^^^^^^^^^^^^^^^^#x1B[90m#x1B[39;49;00m
#x1B[1m#x1B[31mE   AttributeError: 'coroutine' object has no attribute 'network_passphrase'#x1B[0m</failure></testcase><testcase classname="tests.integration.test_real_world_validation.TestRealWorldNetworkValidation" name="test_soroban_rpc_connectivity" time="0.010"><failure message="ValueError: Duplicated timeseries in CollectorRegistry: {'stellar_observability_events', 'stellar_observability_events_created', 'stellar_observability_events_total'}">#x1B[1m#x1B[31mtests/integration/test_real_world_validation.py#x1B[0m:100: in test_soroban_rpc_connectivity
    #x1B[0mconfig=testnet_config, security_framework=#x1B[94mNone#x1B[39;49;00m, observability=StellarObservabilityFramework()#x1B[90m#x1B[39;49;00m
                                                                  ^^^^^^^^^^^^^^^^^^^^^^^^^^^^^^^#x1B[90m#x1B[39;49;00m
#x1B[1m#x1B[31mhummingbot/connector/exchange/stellar/stellar_observability.py#x1B[0m:166: in __init__
    #x1B[0m#x1B[96mself#x1B[39;49;00m._init_production_metrics()#x1B[90m#x1B[39;49;00m
#x1B[1m#x1B[31mhummingbot/connector/exchange/stellar/stellar_observability.py#x1B[0m:174: in _init_production_metrics
    #x1B[0m#x1B[96mself#x1B[39;49;00m.observability_events = Counter(#x1B[90m#x1B[39;49;00m
#x1B[1m#x1B[31mvenv/lib/python3.11/site-packages/prometheus_client/metrics.py#x1B[0m:132: in __init__
    #x1B[0mregistry.register(#x1B[96mself#x1B[39;49;00m)#x1B[90m#x1B[39;49;00m
#x1B[1m#x1B[31mvenv/lib/python3.11/site-packages/prometheus_client/registry.py#x1B[0m:43: in register
    #x1B[0m#x1B[94mraise#x1B[39;49;00m #x1B[96mValueError#x1B[39;49;00m(#x1B[90m#x1B[39;49;00m
#x1B[1m#x1B[31mE   ValueError: Duplicated timeseries in CollectorRegistry: {'stellar_observability_events', 'stellar_observability_events_created', 'stellar_observability_events_total'}#x1B[0m</failure></testcase><testcase classname="tests.integration.test_real_world_validation.TestRealWorldNetworkValidation" name="test_network_failover_resilience" time="0.023"><failure message="pydantic_core._pydantic_core.ValidationError: 4 validation errors for StellarNetworkConfig&#10;network_passphrase&#10;  Field required [type=missing, input_value={'name': 'testnet_failove...testnet-2.stellar.org']}, input_type=dict]&#10;    For further information visit https://errors.pydantic.dev/2.11/v/missing&#10;horizon&#10;  Field required [type=missing, input_value={'name': 'testnet_failove...testnet-2.stellar.org']}, input_type=dict]&#10;    For further information visit https://errors.pydantic.dev/2.11/v/missing&#10;soroban&#10;  Field required [type=missing, input_value={'name': 'testnet_failove...testnet-2.stellar.org']}, input_type=dict]&#10;    For further information visit https://errors.pydantic.dev/2.11/v/missing&#10;rate_limits&#10;  Field required [type=missing, input_value={'name': 'testnet_failove...testnet-2.stellar.org']}, input_type=dict]&#10;    For further information visit https://errors.pydantic.dev/2.11/v/missing">#x1B[1m#x1B[31mtests/integration/test_real_world_validation.py#x1B[0m:116: in test_network_failover_resilience
    #x1B[0mfailover_config = StellarNetworkConfig(#x1B[90m#x1B[39;49;00m
#x1B[1m#x1B[31mE   pydantic_core._pydantic_core.ValidationError: 4 validation errors for StellarNetworkConfig#x1B[0m
#x1B[1m#x1B[31mE   network_passphrase#x1B[0m
#x1B[1m#x1B[31mE     Field required [type=missing, input_value={'name': 'testnet_failove...testnet-2.stellar.org']}, input_type=dict]#x1B[0m
#x1B[1m#x1B[31mE       For further information visit https://errors.pydantic.dev/2.11/v/missing#x1B[0m
#x1B[1m#x1B[31mE   horizon#x1B[0m
#x1B[1m#x1B[31mE     Field required [type=missing, input_value={'name': 'testnet_failove...testnet-2.stellar.org']}, input_type=dict]#x1B[0m
#x1B[1m#x1B[31mE       For further information visit https://errors.pydantic.dev/2.11/v/missing#x1B[0m
#x1B[1m#x1B[31mE   soroban#x1B[0m
#x1B[1m#x1B[31mE     Field required [type=missing, input_value={'name': 'testnet_failove...testnet-2.stellar.org']}, input_type=dict]#x1B[0m
#x1B[1m#x1B[31mE       For further information visit https://errors.pydantic.dev/2.11/v/missing#x1B[0m
#x1B[1m#x1B[31mE   rate_limits#x1B[0m
#x1B[1m#x1B[31mE     Field required [type=missing, input_value={'name': 'testnet_failove...testnet-2.stellar.org']}, input_type=dict]#x1B[0m
#x1B[1m#x1B[31mE       For further information visit https://errors.pydantic.dev/2.11/v/missing#x1B[0m</failure></testcase></testsuite></testsuites>